[2025-01-03T13:39:29.352+0000] {local_task_job_runner.py:123} INFO - ::group::Pre task execution logs
[2025-01-03T13:39:29.360+0000] {taskinstance.py:2612} INFO - Dependencies all met for dep_context=non-requeueable deps ti=<TaskInstance: etl.replicate manual__2025-01-03T13:26:53.564501+00:00 [queued]>
[2025-01-03T13:39:29.364+0000] {taskinstance.py:2612} INFO - Dependencies all met for dep_context=requeueable deps ti=<TaskInstance: etl.replicate manual__2025-01-03T13:26:53.564501+00:00 [queued]>
[2025-01-03T13:39:29.364+0000] {taskinstance.py:2865} INFO - Starting attempt 10 of 10
[2025-01-03T13:39:29.369+0000] {taskinstance.py:2888} INFO - Executing <Task(_PythonDecoratedOperator): replicate> on 2025-01-03 13:26:53.564501+00:00
[2025-01-03T13:39:29.375+0000] {standard_task_runner.py:104} INFO - Running: ['***', 'tasks', 'run', 'etl', 'replicate', 'manual__2025-01-03T13:26:53.564501+00:00', '--job-id', '23', '--raw', '--subdir', 'DAGS_FOLDER/etl.py', '--cfg-path', '/tmp/tmp5spg8jh7']
[2025-01-03T13:39:29.373+0000] {warnings.py:112} WARNING - /home/***/.local/lib/python3.12/site-packages/***/task/task_runner/standard_task_runner.py:70: DeprecationWarning: This process (pid=661) is multi-threaded, use of fork() may lead to deadlocks in the child.
  pid = os.fork()

[2025-01-03T13:39:29.379+0000] {standard_task_runner.py:72} INFO - Started process 662 to run task
[2025-01-03T13:39:29.378+0000] {standard_task_runner.py:105} INFO - Job 23: Subtask replicate
[2025-01-03T13:39:29.413+0000] {task_command.py:467} INFO - Running <TaskInstance: etl.replicate manual__2025-01-03T13:26:53.564501+00:00 [running]> on host f6c52e409999
[2025-01-03T13:39:29.459+0000] {taskinstance.py:3131} INFO - Exporting env vars: AIRFLOW_CTX_DAG_OWNER='***' AIRFLOW_CTX_DAG_ID='etl' AIRFLOW_CTX_TASK_ID='replicate' AIRFLOW_CTX_EXECUTION_DATE='2025-01-03T13:26:53.564501+00:00' AIRFLOW_CTX_TRY_NUMBER='10' AIRFLOW_CTX_DAG_RUN_ID='manual__2025-01-03T13:26:53.564501+00:00'
[2025-01-03T13:39:29.460+0000] {taskinstance.py:731} INFO - ::endgroup::
[2025-01-03T13:39:29.908+0000] {crypto.py:82} WARNING - empty cryptography key - values will not be stored encrypted.
[2025-01-03T13:39:29.909+0000] {base.py:84} INFO - Retrieving connection 'postgres'
[2025-01-03T13:39:29.923+0000] {base.py:84} INFO - Retrieving connection 'mysql'
[2025-01-03T13:39:29.937+0000] {logging_mixin.py:190} INFO - [(UUID('7deec2b6-180f-4fc5-acd5-758ba2c8c3ca'), 'smartphohe', None), (UUID('233d515a-dcbd-4bbb-9c04-339c6b718285'), 'tablet', None), (UUID('1e69f0e1-e072-41e6-be84-3a76830826a6'), 'laptop', None), (UUID('197444fa-418c-4bdd-af82-f56a2f2f7d4a'), 'desktop', None)]
[2025-01-03T13:39:29.938+0000] {logging_mixin.py:190} INFO - Table Database.PRODUCT_CATEGORIES has 4 rows
[2025-01-03T13:39:29.938+0000] {taskinstance.py:3310} ERROR - Task failed with exception
Traceback (most recent call last):
  File "/home/airflow/.local/lib/python3.12/site-packages/airflow/models/taskinstance.py", line 767, in _execute_task
    result = _execute_callable(context=context, **execute_callable_kwargs)
             ^^^^^^^^^^^^^^^^^^^^^^^^^^^^^^^^^^^^^^^^^^^^^^^^^^^^^^^^^^^^^
  File "/home/airflow/.local/lib/python3.12/site-packages/airflow/models/taskinstance.py", line 733, in _execute_callable
    return ExecutionCallableRunner(
           ^^^^^^^^^^^^^^^^^^^^^^^^
  File "/home/airflow/.local/lib/python3.12/site-packages/airflow/utils/operator_helpers.py", line 252, in run
    return self.func(*args, **kwargs)
           ^^^^^^^^^^^^^^^^^^^^^^^^^^
  File "/home/airflow/.local/lib/python3.12/site-packages/airflow/models/baseoperator.py", line 406, in wrapper
    return func(self, *args, **kwargs)
           ^^^^^^^^^^^^^^^^^^^^^^^^^^^
  File "/home/airflow/.local/lib/python3.12/site-packages/airflow/decorators/base.py", line 266, in execute
    return_value = super().execute(context)
                   ^^^^^^^^^^^^^^^^^^^^^^^^
  File "/home/airflow/.local/lib/python3.12/site-packages/airflow/models/baseoperator.py", line 406, in wrapper
    return func(self, *args, **kwargs)
           ^^^^^^^^^^^^^^^^^^^^^^^^^^^
  File "/home/airflow/.local/lib/python3.12/site-packages/airflow/operators/python.py", line 238, in execute
    return_value = self.execute_callable()
                   ^^^^^^^^^^^^^^^^^^^^^^^
  File "/home/airflow/.local/lib/python3.12/site-packages/airflow/operators/python.py", line 256, in execute_callable
    return runner.run(*self.op_args, **self.op_kwargs)
           ^^^^^^^^^^^^^^^^^^^^^^^^^^^^^^^^^^^^^^^^^^^
  File "/home/airflow/.local/lib/python3.12/site-packages/airflow/utils/operator_helpers.py", line 252, in run
    return self.func(*args, **kwargs)
           ^^^^^^^^^^^^^^^^^^^^^^^^^^
  File "/opt/airflow/dags/etl.py", line 137, in replicate
    ms_connection.commit()
MySQLdb.ProgrammingError: (2014, "Commands out of sync; you can't run this command now")
[2025-01-03T13:39:29.949+0000] {taskinstance.py:1225} INFO - Marking task as FAILED. dag_id=etl, task_id=replicate, run_id=manual__2025-01-03T13:26:53.564501+00:00, execution_date=20250103T132653, start_date=20250103T133929, end_date=20250103T133929
[2025-01-03T13:39:29.956+0000] {taskinstance.py:340} INFO - ::group::Post task execution logs
[2025-01-03T13:39:29.956+0000] {standard_task_runner.py:124} ERROR - Failed to execute job 23 for task replicate ((2014, "Commands out of sync; you can't run this command now"); 662)
Traceback (most recent call last):
  File "/home/airflow/.local/lib/python3.12/site-packages/airflow/task/task_runner/standard_task_runner.py", line 117, in _start_by_fork
    ret = args.func(args, dag=self.dag)
          ^^^^^^^^^^^^^^^^^^^^^^^^^^^^^
  File "/home/airflow/.local/lib/python3.12/site-packages/airflow/cli/cli_config.py", line 49, in command
    return func(*args, **kwargs)
           ^^^^^^^^^^^^^^^^^^^^^
  File "/home/airflow/.local/lib/python3.12/site-packages/airflow/utils/cli.py", line 115, in wrapper
    return f(*args, **kwargs)
           ^^^^^^^^^^^^^^^^^^
  File "/home/airflow/.local/lib/python3.12/site-packages/airflow/cli/commands/task_command.py", line 483, in task_run
    task_return_code = _run_task_by_selected_method(args, _dag, ti)
                       ^^^^^^^^^^^^^^^^^^^^^^^^^^^^^^^^^^^^^^^^^^^^
  File "/home/airflow/.local/lib/python3.12/site-packages/airflow/cli/commands/task_command.py", line 256, in _run_task_by_selected_method
    return _run_raw_task(args, ti)
           ^^^^^^^^^^^^^^^^^^^^^^^
  File "/home/airflow/.local/lib/python3.12/site-packages/airflow/cli/commands/task_command.py", line 341, in _run_raw_task
    return ti._run_raw_task(
           ^^^^^^^^^^^^^^^^^
  File "/home/airflow/.local/lib/python3.12/site-packages/airflow/utils/session.py", line 97, in wrapper
    return func(*args, session=session, **kwargs)
           ^^^^^^^^^^^^^^^^^^^^^^^^^^^^^^^^^^^^^^
  File "/home/airflow/.local/lib/python3.12/site-packages/airflow/models/taskinstance.py", line 3004, in _run_raw_task
    return _run_raw_task(
           ^^^^^^^^^^^^^^
  File "/home/airflow/.local/lib/python3.12/site-packages/airflow/models/taskinstance.py", line 273, in _run_raw_task
    TaskInstance._execute_task_with_callbacks(
  File "/home/airflow/.local/lib/python3.12/site-packages/airflow/models/taskinstance.py", line 3158, in _execute_task_with_callbacks
    result = self._execute_task(context, task_orig)
             ^^^^^^^^^^^^^^^^^^^^^^^^^^^^^^^^^^^^^^
  File "/home/airflow/.local/lib/python3.12/site-packages/airflow/models/taskinstance.py", line 3182, in _execute_task
    return _execute_task(self, context, task_orig)
           ^^^^^^^^^^^^^^^^^^^^^^^^^^^^^^^^^^^^^^^
  File "/home/airflow/.local/lib/python3.12/site-packages/airflow/models/taskinstance.py", line 767, in _execute_task
    result = _execute_callable(context=context, **execute_callable_kwargs)
             ^^^^^^^^^^^^^^^^^^^^^^^^^^^^^^^^^^^^^^^^^^^^^^^^^^^^^^^^^^^^^
  File "/home/airflow/.local/lib/python3.12/site-packages/airflow/models/taskinstance.py", line 733, in _execute_callable
    return ExecutionCallableRunner(
           ^^^^^^^^^^^^^^^^^^^^^^^^
  File "/home/airflow/.local/lib/python3.12/site-packages/airflow/utils/operator_helpers.py", line 252, in run
    return self.func(*args, **kwargs)
           ^^^^^^^^^^^^^^^^^^^^^^^^^^
  File "/home/airflow/.local/lib/python3.12/site-packages/airflow/models/baseoperator.py", line 406, in wrapper
    return func(self, *args, **kwargs)
           ^^^^^^^^^^^^^^^^^^^^^^^^^^^
  File "/home/airflow/.local/lib/python3.12/site-packages/airflow/decorators/base.py", line 266, in execute
    return_value = super().execute(context)
                   ^^^^^^^^^^^^^^^^^^^^^^^^
  File "/home/airflow/.local/lib/python3.12/site-packages/airflow/models/baseoperator.py", line 406, in wrapper
    return func(self, *args, **kwargs)
           ^^^^^^^^^^^^^^^^^^^^^^^^^^^
  File "/home/airflow/.local/lib/python3.12/site-packages/airflow/operators/python.py", line 238, in execute
    return_value = self.execute_callable()
                   ^^^^^^^^^^^^^^^^^^^^^^^
  File "/home/airflow/.local/lib/python3.12/site-packages/airflow/operators/python.py", line 256, in execute_callable
    return runner.run(*self.op_args, **self.op_kwargs)
           ^^^^^^^^^^^^^^^^^^^^^^^^^^^^^^^^^^^^^^^^^^^
  File "/home/airflow/.local/lib/python3.12/site-packages/airflow/utils/operator_helpers.py", line 252, in run
    return self.func(*args, **kwargs)
           ^^^^^^^^^^^^^^^^^^^^^^^^^^
  File "/opt/airflow/dags/etl.py", line 137, in replicate
    ms_connection.commit()
MySQLdb.ProgrammingError: (2014, "Commands out of sync; you can't run this command now")
[2025-01-03T13:39:29.980+0000] {local_task_job_runner.py:266} INFO - Task exited with return code 1
[2025-01-03T13:39:29.990+0000] {taskinstance.py:3900} INFO - 0 downstream tasks scheduled from follow-on schedule check
[2025-01-03T13:39:29.991+0000] {local_task_job_runner.py:245} INFO - ::endgroup::
