[2025-01-03T13:35:14.061+0000] {local_task_job_runner.py:123} INFO - ::group::Pre task execution logs
[2025-01-03T13:35:14.070+0000] {taskinstance.py:2612} INFO - Dependencies all met for dep_context=non-requeueable deps ti=<TaskInstance: etl.replicate manual__2025-01-03T13:26:53.564501+00:00 [queued]>
[2025-01-03T13:35:14.074+0000] {taskinstance.py:2612} INFO - Dependencies all met for dep_context=requeueable deps ti=<TaskInstance: etl.replicate manual__2025-01-03T13:26:53.564501+00:00 [queued]>
[2025-01-03T13:35:14.074+0000] {taskinstance.py:2865} INFO - Starting attempt 5 of 5
[2025-01-03T13:35:14.080+0000] {taskinstance.py:2888} INFO - Executing <Task(_PythonDecoratedOperator): replicate> on 2025-01-03 13:26:53.564501+00:00
[2025-01-03T13:35:14.084+0000] {warnings.py:112} WARNING - /home/***/.local/lib/python3.12/site-packages/***/task/task_runner/standard_task_runner.py:70: DeprecationWarning: This process (pid=585) is multi-threaded, use of fork() may lead to deadlocks in the child.
  pid = os.fork()

[2025-01-03T13:35:14.086+0000] {standard_task_runner.py:72} INFO - Started process 586 to run task
[2025-01-03T13:35:14.087+0000] {standard_task_runner.py:104} INFO - Running: ['***', 'tasks', 'run', 'etl', 'replicate', 'manual__2025-01-03T13:26:53.564501+00:00', '--job-id', '18', '--raw', '--subdir', 'DAGS_FOLDER/etl.py', '--cfg-path', '/tmp/tmpdm3n1_lx']
[2025-01-03T13:35:14.089+0000] {standard_task_runner.py:105} INFO - Job 18: Subtask replicate
[2025-01-03T13:35:14.116+0000] {task_command.py:467} INFO - Running <TaskInstance: etl.replicate manual__2025-01-03T13:26:53.564501+00:00 [running]> on host f6c52e409999
[2025-01-03T13:35:14.162+0000] {taskinstance.py:3131} INFO - Exporting env vars: AIRFLOW_CTX_DAG_OWNER='***' AIRFLOW_CTX_DAG_ID='etl' AIRFLOW_CTX_TASK_ID='replicate' AIRFLOW_CTX_EXECUTION_DATE='2025-01-03T13:26:53.564501+00:00' AIRFLOW_CTX_TRY_NUMBER='5' AIRFLOW_CTX_DAG_RUN_ID='manual__2025-01-03T13:26:53.564501+00:00'
[2025-01-03T13:35:14.163+0000] {taskinstance.py:731} INFO - ::endgroup::
[2025-01-03T13:35:14.584+0000] {crypto.py:82} WARNING - empty cryptography key - values will not be stored encrypted.
[2025-01-03T13:35:14.586+0000] {base.py:84} INFO - Retrieving connection 'postgres'
[2025-01-03T13:35:14.598+0000] {base.py:84} INFO - Retrieving connection 'mysql'
[2025-01-03T13:35:14.609+0000] {logging_mixin.py:190} INFO - Table Database.PRODUCT_CATEGORIES has 1 rows
[2025-01-03T13:35:14.621+0000] {taskinstance.py:3310} ERROR - Task failed with exception
Traceback (most recent call last):
  File "/home/airflow/.local/lib/python3.12/site-packages/sqlalchemy/engine/base.py", line 1910, in _execute_context
    self.dialect.do_execute(
  File "/home/airflow/.local/lib/python3.12/site-packages/sqlalchemy/engine/default.py", line 736, in do_execute
    cursor.execute(statement, parameters)
  File "/home/airflow/.local/lib/python3.12/site-packages/MySQLdb/cursors.py", line 179, in execute
    res = self._query(mogrified_query)
          ^^^^^^^^^^^^^^^^^^^^^^^^^^^^
  File "/home/airflow/.local/lib/python3.12/site-packages/MySQLdb/cursors.py", line 330, in _query
    db.query(q)
  File "/home/airflow/.local/lib/python3.12/site-packages/MySQLdb/connections.py", line 261, in query
    _mysql.connection.query(self, query)
MySQLdb.OperationalError: (1059, "Identifier name 'Field(name='category_id',type=<class 'uuid.UUID'>,default=<dataclasses._MISSING_TYPE object at 0xfff' is too long")

The above exception was the direct cause of the following exception:

Traceback (most recent call last):
  File "/home/airflow/.local/lib/python3.12/site-packages/airflow/models/taskinstance.py", line 767, in _execute_task
    result = _execute_callable(context=context, **execute_callable_kwargs)
             ^^^^^^^^^^^^^^^^^^^^^^^^^^^^^^^^^^^^^^^^^^^^^^^^^^^^^^^^^^^^^
  File "/home/airflow/.local/lib/python3.12/site-packages/airflow/models/taskinstance.py", line 733, in _execute_callable
    return ExecutionCallableRunner(
           ^^^^^^^^^^^^^^^^^^^^^^^^
  File "/home/airflow/.local/lib/python3.12/site-packages/airflow/utils/operator_helpers.py", line 252, in run
    return self.func(*args, **kwargs)
           ^^^^^^^^^^^^^^^^^^^^^^^^^^
  File "/home/airflow/.local/lib/python3.12/site-packages/airflow/models/baseoperator.py", line 406, in wrapper
    return func(self, *args, **kwargs)
           ^^^^^^^^^^^^^^^^^^^^^^^^^^^
  File "/home/airflow/.local/lib/python3.12/site-packages/airflow/decorators/base.py", line 266, in execute
    return_value = super().execute(context)
                   ^^^^^^^^^^^^^^^^^^^^^^^^
  File "/home/airflow/.local/lib/python3.12/site-packages/airflow/models/baseoperator.py", line 406, in wrapper
    return func(self, *args, **kwargs)
           ^^^^^^^^^^^^^^^^^^^^^^^^^^^
  File "/home/airflow/.local/lib/python3.12/site-packages/airflow/operators/python.py", line 238, in execute
    return_value = self.execute_callable()
                   ^^^^^^^^^^^^^^^^^^^^^^^
  File "/home/airflow/.local/lib/python3.12/site-packages/airflow/operators/python.py", line 256, in execute_callable
    return runner.run(*self.op_args, **self.op_kwargs)
           ^^^^^^^^^^^^^^^^^^^^^^^^^^^^^^^^^^^^^^^^^^^
  File "/home/airflow/.local/lib/python3.12/site-packages/airflow/utils/operator_helpers.py", line 252, in run
    return self.func(*args, **kwargs)
           ^^^^^^^^^^^^^^^^^^^^^^^^^^
  File "/opt/airflow/dags/etl.py", line 137, in replicate
    df.to_sql(f"db.{table.table_name}", ms_engine, if_exists="append", index=False)
  File "/home/airflow/.local/lib/python3.12/site-packages/pandas/util/_decorators.py", line 333, in wrapper
    return func(*args, **kwargs)
           ^^^^^^^^^^^^^^^^^^^^^
  File "/home/airflow/.local/lib/python3.12/site-packages/pandas/core/generic.py", line 3008, in to_sql
    return sql.to_sql(
           ^^^^^^^^^^^
  File "/home/airflow/.local/lib/python3.12/site-packages/pandas/io/sql.py", line 788, in to_sql
    return pandas_sql.to_sql(
           ^^^^^^^^^^^^^^^^^^
  File "/home/airflow/.local/lib/python3.12/site-packages/pandas/io/sql.py", line 1948, in to_sql
    table = self.prep_table(
            ^^^^^^^^^^^^^^^^
  File "/home/airflow/.local/lib/python3.12/site-packages/pandas/io/sql.py", line 1852, in prep_table
    table.create()
  File "/home/airflow/.local/lib/python3.12/site-packages/pandas/io/sql.py", line 936, in create
    self._execute_create()
  File "/home/airflow/.local/lib/python3.12/site-packages/pandas/io/sql.py", line 922, in _execute_create
    self.table.create(bind=self.pd_sql.con)
  File "/home/airflow/.local/lib/python3.12/site-packages/sqlalchemy/sql/schema.py", line 962, in create
    bind._run_ddl_visitor(ddl.SchemaGenerator, self, checkfirst=checkfirst)
  File "/home/airflow/.local/lib/python3.12/site-packages/sqlalchemy/engine/base.py", line 2221, in _run_ddl_visitor
    visitorcallable(self.dialect, self, **kwargs).traverse_single(element)
  File "/home/airflow/.local/lib/python3.12/site-packages/sqlalchemy/sql/visitors.py", line 524, in traverse_single
    return meth(obj, **kw)
           ^^^^^^^^^^^^^^^
  File "/home/airflow/.local/lib/python3.12/site-packages/sqlalchemy/sql/ddl.py", line 899, in visit_table
    self.connection.execute(
  File "/home/airflow/.local/lib/python3.12/site-packages/sqlalchemy/engine/base.py", line 1385, in execute
    return meth(self, multiparams, params, _EMPTY_EXECUTION_OPTS)
           ^^^^^^^^^^^^^^^^^^^^^^^^^^^^^^^^^^^^^^^^^^^^^^^^^^^^^^
  File "/home/airflow/.local/lib/python3.12/site-packages/sqlalchemy/sql/ddl.py", line 80, in _execute_on_connection
    return connection._execute_ddl(
           ^^^^^^^^^^^^^^^^^^^^^^^^
  File "/home/airflow/.local/lib/python3.12/site-packages/sqlalchemy/engine/base.py", line 1477, in _execute_ddl
    ret = self._execute_context(
          ^^^^^^^^^^^^^^^^^^^^^^
  File "/home/airflow/.local/lib/python3.12/site-packages/sqlalchemy/engine/base.py", line 1953, in _execute_context
    self._handle_dbapi_exception(
  File "/home/airflow/.local/lib/python3.12/site-packages/sqlalchemy/engine/base.py", line 2134, in _handle_dbapi_exception
    util.raise_(
  File "/home/airflow/.local/lib/python3.12/site-packages/sqlalchemy/util/compat.py", line 211, in raise_
    raise exception
  File "/home/airflow/.local/lib/python3.12/site-packages/sqlalchemy/engine/base.py", line 1910, in _execute_context
    self.dialect.do_execute(
  File "/home/airflow/.local/lib/python3.12/site-packages/sqlalchemy/engine/default.py", line 736, in do_execute
    cursor.execute(statement, parameters)
  File "/home/airflow/.local/lib/python3.12/site-packages/MySQLdb/cursors.py", line 179, in execute
    res = self._query(mogrified_query)
          ^^^^^^^^^^^^^^^^^^^^^^^^^^^^
  File "/home/airflow/.local/lib/python3.12/site-packages/MySQLdb/cursors.py", line 330, in _query
    db.query(q)
  File "/home/airflow/.local/lib/python3.12/site-packages/MySQLdb/connections.py", line 261, in query
    _mysql.connection.query(self, query)
sqlalchemy.exc.OperationalError: (MySQLdb.OperationalError) (1059, "Identifier name 'Field(name='category_id',type=<class 'uuid.UUID'>,default=<dataclasses._MISSING_TYPE object at 0xfff' is too long")
[SQL: 
CREATE TABLE `db.product_categories` (
	`Field(name='category_id',type=<class 'uuid.UUID'>,default=<dataclasses._MISSING_TYPE object at 0xffffaf90f1a0>,default_factory=<dataclasses._MISSING_TYPE object at 0xffffaf90f1a0>,init=True,repr=True,hash=None,compare=True,metadata=mappingproxy({}),kw_only=False,_field_type=_FIELD)` TEXT, 
	`Field(name='name',type=<enum 'ProductCategoryEnum'>,default=<dataclasses._MISSING_TYPE object at 0xffffaf90f1a0>,default_factory=<dataclasses._MISSING_TYPE object at 0xffffaf90f1a0>,init=True,repr=True,hash=None,compare=True,metadata=mappingproxy({}),kw_only=False,_field_type=_FIELD)` TEXT, 
	`Field(name='parent_category_id',type=<class 'uuid.UUID'>,default=<dataclasses._MISSING_TYPE object at 0xffffaf90f1a0>,default_factory=<dataclasses._MISSING_TYPE object at 0xffffaf90f1a0>,init=True,repr=True,hash=None,compare=True,metadata=mappingproxy({}),kw_only=False,_field_type=_FIELD)` TEXT
)

]
(Background on this error at: https://sqlalche.me/e/14/e3q8)
[2025-01-03T13:35:14.633+0000] {taskinstance.py:1225} INFO - Marking task as FAILED. dag_id=etl, task_id=replicate, run_id=manual__2025-01-03T13:26:53.564501+00:00, execution_date=20250103T132653, start_date=20250103T133514, end_date=20250103T133514
[2025-01-03T13:35:14.638+0000] {taskinstance.py:340} INFO - ::group::Post task execution logs
[2025-01-03T13:35:14.639+0000] {standard_task_runner.py:124} ERROR - Failed to execute job 18 for task replicate ((MySQLdb.OperationalError) (1059, "Identifier name 'Field(name='category_id',type=<class 'uuid.UUID'>,default=<dataclasses._MISSING_TYPE object at 0xfff' is too long")
[SQL: 
CREATE TABLE `db.product_categories` (
	`Field(name='category_id',type=<class 'uuid.UUID'>,default=<dataclasses._MISSING_TYPE object at 0xffffaf90f1a0>,default_factory=<dataclasses._MISSING_TYPE object at 0xffffaf90f1a0>,init=True,repr=True,hash=None,compare=True,metadata=mappingproxy({}),kw_only=False,_field_type=_FIELD)` TEXT, 
	`Field(name='name',type=<enum 'ProductCategoryEnum'>,default=<dataclasses._MISSING_TYPE object at 0xffffaf90f1a0>,default_factory=<dataclasses._MISSING_TYPE object at 0xffffaf90f1a0>,init=True,repr=True,hash=None,compare=True,metadata=mappingproxy({}),kw_only=False,_field_type=_FIELD)` TEXT, 
	`Field(name='parent_category_id',type=<class 'uuid.UUID'>,default=<dataclasses._MISSING_TYPE object at 0xffffaf90f1a0>,default_factory=<dataclasses._MISSING_TYPE object at 0xffffaf90f1a0>,init=True,repr=True,hash=None,compare=True,metadata=mappingproxy({}),kw_only=False,_field_type=_FIELD)` TEXT
)

]
(Background on this error at: https://sqlalche.me/e/14/e3q8); 586)
Traceback (most recent call last):
  File "/home/airflow/.local/lib/python3.12/site-packages/sqlalchemy/engine/base.py", line 1910, in _execute_context
    self.dialect.do_execute(
  File "/home/airflow/.local/lib/python3.12/site-packages/sqlalchemy/engine/default.py", line 736, in do_execute
    cursor.execute(statement, parameters)
  File "/home/airflow/.local/lib/python3.12/site-packages/MySQLdb/cursors.py", line 179, in execute
    res = self._query(mogrified_query)
          ^^^^^^^^^^^^^^^^^^^^^^^^^^^^
  File "/home/airflow/.local/lib/python3.12/site-packages/MySQLdb/cursors.py", line 330, in _query
    db.query(q)
  File "/home/airflow/.local/lib/python3.12/site-packages/MySQLdb/connections.py", line 261, in query
    _mysql.connection.query(self, query)
MySQLdb.OperationalError: (1059, "Identifier name 'Field(name='category_id',type=<class 'uuid.UUID'>,default=<dataclasses._MISSING_TYPE object at 0xfff' is too long")

The above exception was the direct cause of the following exception:

Traceback (most recent call last):
  File "/home/airflow/.local/lib/python3.12/site-packages/airflow/task/task_runner/standard_task_runner.py", line 117, in _start_by_fork
    ret = args.func(args, dag=self.dag)
          ^^^^^^^^^^^^^^^^^^^^^^^^^^^^^
  File "/home/airflow/.local/lib/python3.12/site-packages/airflow/cli/cli_config.py", line 49, in command
    return func(*args, **kwargs)
           ^^^^^^^^^^^^^^^^^^^^^
  File "/home/airflow/.local/lib/python3.12/site-packages/airflow/utils/cli.py", line 115, in wrapper
    return f(*args, **kwargs)
           ^^^^^^^^^^^^^^^^^^
  File "/home/airflow/.local/lib/python3.12/site-packages/airflow/cli/commands/task_command.py", line 483, in task_run
    task_return_code = _run_task_by_selected_method(args, _dag, ti)
                       ^^^^^^^^^^^^^^^^^^^^^^^^^^^^^^^^^^^^^^^^^^^^
  File "/home/airflow/.local/lib/python3.12/site-packages/airflow/cli/commands/task_command.py", line 256, in _run_task_by_selected_method
    return _run_raw_task(args, ti)
           ^^^^^^^^^^^^^^^^^^^^^^^
  File "/home/airflow/.local/lib/python3.12/site-packages/airflow/cli/commands/task_command.py", line 341, in _run_raw_task
    return ti._run_raw_task(
           ^^^^^^^^^^^^^^^^^
  File "/home/airflow/.local/lib/python3.12/site-packages/airflow/utils/session.py", line 97, in wrapper
    return func(*args, session=session, **kwargs)
           ^^^^^^^^^^^^^^^^^^^^^^^^^^^^^^^^^^^^^^
  File "/home/airflow/.local/lib/python3.12/site-packages/airflow/models/taskinstance.py", line 3004, in _run_raw_task
    return _run_raw_task(
           ^^^^^^^^^^^^^^
  File "/home/airflow/.local/lib/python3.12/site-packages/airflow/models/taskinstance.py", line 273, in _run_raw_task
    TaskInstance._execute_task_with_callbacks(
  File "/home/airflow/.local/lib/python3.12/site-packages/airflow/models/taskinstance.py", line 3158, in _execute_task_with_callbacks
    result = self._execute_task(context, task_orig)
             ^^^^^^^^^^^^^^^^^^^^^^^^^^^^^^^^^^^^^^
  File "/home/airflow/.local/lib/python3.12/site-packages/airflow/models/taskinstance.py", line 3182, in _execute_task
    return _execute_task(self, context, task_orig)
           ^^^^^^^^^^^^^^^^^^^^^^^^^^^^^^^^^^^^^^^
  File "/home/airflow/.local/lib/python3.12/site-packages/airflow/models/taskinstance.py", line 767, in _execute_task
    result = _execute_callable(context=context, **execute_callable_kwargs)
             ^^^^^^^^^^^^^^^^^^^^^^^^^^^^^^^^^^^^^^^^^^^^^^^^^^^^^^^^^^^^^
  File "/home/airflow/.local/lib/python3.12/site-packages/airflow/models/taskinstance.py", line 733, in _execute_callable
    return ExecutionCallableRunner(
           ^^^^^^^^^^^^^^^^^^^^^^^^
  File "/home/airflow/.local/lib/python3.12/site-packages/airflow/utils/operator_helpers.py", line 252, in run
    return self.func(*args, **kwargs)
           ^^^^^^^^^^^^^^^^^^^^^^^^^^
  File "/home/airflow/.local/lib/python3.12/site-packages/airflow/models/baseoperator.py", line 406, in wrapper
    return func(self, *args, **kwargs)
           ^^^^^^^^^^^^^^^^^^^^^^^^^^^
  File "/home/airflow/.local/lib/python3.12/site-packages/airflow/decorators/base.py", line 266, in execute
    return_value = super().execute(context)
                   ^^^^^^^^^^^^^^^^^^^^^^^^
  File "/home/airflow/.local/lib/python3.12/site-packages/airflow/models/baseoperator.py", line 406, in wrapper
    return func(self, *args, **kwargs)
           ^^^^^^^^^^^^^^^^^^^^^^^^^^^
  File "/home/airflow/.local/lib/python3.12/site-packages/airflow/operators/python.py", line 238, in execute
    return_value = self.execute_callable()
                   ^^^^^^^^^^^^^^^^^^^^^^^
  File "/home/airflow/.local/lib/python3.12/site-packages/airflow/operators/python.py", line 256, in execute_callable
    return runner.run(*self.op_args, **self.op_kwargs)
           ^^^^^^^^^^^^^^^^^^^^^^^^^^^^^^^^^^^^^^^^^^^
  File "/home/airflow/.local/lib/python3.12/site-packages/airflow/utils/operator_helpers.py", line 252, in run
    return self.func(*args, **kwargs)
           ^^^^^^^^^^^^^^^^^^^^^^^^^^
  File "/opt/airflow/dags/etl.py", line 137, in replicate
    df.to_sql(f"db.{table.table_name}", ms_engine, if_exists="append", index=False)
  File "/home/airflow/.local/lib/python3.12/site-packages/pandas/util/_decorators.py", line 333, in wrapper
    return func(*args, **kwargs)
           ^^^^^^^^^^^^^^^^^^^^^
  File "/home/airflow/.local/lib/python3.12/site-packages/pandas/core/generic.py", line 3008, in to_sql
    return sql.to_sql(
           ^^^^^^^^^^^
  File "/home/airflow/.local/lib/python3.12/site-packages/pandas/io/sql.py", line 788, in to_sql
    return pandas_sql.to_sql(
           ^^^^^^^^^^^^^^^^^^
  File "/home/airflow/.local/lib/python3.12/site-packages/pandas/io/sql.py", line 1948, in to_sql
    table = self.prep_table(
            ^^^^^^^^^^^^^^^^
  File "/home/airflow/.local/lib/python3.12/site-packages/pandas/io/sql.py", line 1852, in prep_table
    table.create()
  File "/home/airflow/.local/lib/python3.12/site-packages/pandas/io/sql.py", line 936, in create
    self._execute_create()
  File "/home/airflow/.local/lib/python3.12/site-packages/pandas/io/sql.py", line 922, in _execute_create
    self.table.create(bind=self.pd_sql.con)
  File "/home/airflow/.local/lib/python3.12/site-packages/sqlalchemy/sql/schema.py", line 962, in create
    bind._run_ddl_visitor(ddl.SchemaGenerator, self, checkfirst=checkfirst)
  File "/home/airflow/.local/lib/python3.12/site-packages/sqlalchemy/engine/base.py", line 2221, in _run_ddl_visitor
    visitorcallable(self.dialect, self, **kwargs).traverse_single(element)
  File "/home/airflow/.local/lib/python3.12/site-packages/sqlalchemy/sql/visitors.py", line 524, in traverse_single
    return meth(obj, **kw)
           ^^^^^^^^^^^^^^^
  File "/home/airflow/.local/lib/python3.12/site-packages/sqlalchemy/sql/ddl.py", line 899, in visit_table
    self.connection.execute(
  File "/home/airflow/.local/lib/python3.12/site-packages/sqlalchemy/engine/base.py", line 1385, in execute
    return meth(self, multiparams, params, _EMPTY_EXECUTION_OPTS)
           ^^^^^^^^^^^^^^^^^^^^^^^^^^^^^^^^^^^^^^^^^^^^^^^^^^^^^^
  File "/home/airflow/.local/lib/python3.12/site-packages/sqlalchemy/sql/ddl.py", line 80, in _execute_on_connection
    return connection._execute_ddl(
           ^^^^^^^^^^^^^^^^^^^^^^^^
  File "/home/airflow/.local/lib/python3.12/site-packages/sqlalchemy/engine/base.py", line 1477, in _execute_ddl
    ret = self._execute_context(
          ^^^^^^^^^^^^^^^^^^^^^^
  File "/home/airflow/.local/lib/python3.12/site-packages/sqlalchemy/engine/base.py", line 1953, in _execute_context
    self._handle_dbapi_exception(
  File "/home/airflow/.local/lib/python3.12/site-packages/sqlalchemy/engine/base.py", line 2134, in _handle_dbapi_exception
    util.raise_(
  File "/home/airflow/.local/lib/python3.12/site-packages/sqlalchemy/util/compat.py", line 211, in raise_
    raise exception
  File "/home/airflow/.local/lib/python3.12/site-packages/sqlalchemy/engine/base.py", line 1910, in _execute_context
    self.dialect.do_execute(
  File "/home/airflow/.local/lib/python3.12/site-packages/sqlalchemy/engine/default.py", line 736, in do_execute
    cursor.execute(statement, parameters)
  File "/home/airflow/.local/lib/python3.12/site-packages/MySQLdb/cursors.py", line 179, in execute
    res = self._query(mogrified_query)
          ^^^^^^^^^^^^^^^^^^^^^^^^^^^^
  File "/home/airflow/.local/lib/python3.12/site-packages/MySQLdb/cursors.py", line 330, in _query
    db.query(q)
  File "/home/airflow/.local/lib/python3.12/site-packages/MySQLdb/connections.py", line 261, in query
    _mysql.connection.query(self, query)
sqlalchemy.exc.OperationalError: (MySQLdb.OperationalError) (1059, "Identifier name 'Field(name='category_id',type=<class 'uuid.UUID'>,default=<dataclasses._MISSING_TYPE object at 0xfff' is too long")
[SQL: 
CREATE TABLE `db.product_categories` (
	`Field(name='category_id',type=<class 'uuid.UUID'>,default=<dataclasses._MISSING_TYPE object at 0xffffaf90f1a0>,default_factory=<dataclasses._MISSING_TYPE object at 0xffffaf90f1a0>,init=True,repr=True,hash=None,compare=True,metadata=mappingproxy({}),kw_only=False,_field_type=_FIELD)` TEXT, 
	`Field(name='name',type=<enum 'ProductCategoryEnum'>,default=<dataclasses._MISSING_TYPE object at 0xffffaf90f1a0>,default_factory=<dataclasses._MISSING_TYPE object at 0xffffaf90f1a0>,init=True,repr=True,hash=None,compare=True,metadata=mappingproxy({}),kw_only=False,_field_type=_FIELD)` TEXT, 
	`Field(name='parent_category_id',type=<class 'uuid.UUID'>,default=<dataclasses._MISSING_TYPE object at 0xffffaf90f1a0>,default_factory=<dataclasses._MISSING_TYPE object at 0xffffaf90f1a0>,init=True,repr=True,hash=None,compare=True,metadata=mappingproxy({}),kw_only=False,_field_type=_FIELD)` TEXT
)

]
(Background on this error at: https://sqlalche.me/e/14/e3q8)
[2025-01-03T13:35:14.686+0000] {local_task_job_runner.py:266} INFO - Task exited with return code 1
[2025-01-03T13:35:14.696+0000] {taskinstance.py:3900} INFO - 0 downstream tasks scheduled from follow-on schedule check
[2025-01-03T13:35:14.697+0000] {local_task_job_runner.py:245} INFO - ::endgroup::
